timestamp: 2018-06-03T21:14:40.668708
args: ['/home/vzilinas/.cache/pants/setup/bootstrap-Linux-x86_64/1.6.0/bin/pants', 'binary', 'src/python/report-generation-topology']
pid: 21178
Exception caught: (<class 'pants.build_graph.address_lookup_error.AddressLookupError'>)
  File "/home/vzilinas/.cache/pants/setup/bootstrap-Linux-x86_64/1.6.0/bin/pants", line 11, in <module>
    sys.exit(main())
  File "/home/vzilinas/.cache/pants/setup/bootstrap-Linux-x86_64/1.6.0/lib/python2.7/site-packages/pants/bin/pants_loader.py", line 69, in main
    PantsLoader.run()
  File "/home/vzilinas/.cache/pants/setup/bootstrap-Linux-x86_64/1.6.0/lib/python2.7/site-packages/pants/bin/pants_loader.py", line 65, in run
    cls.load_and_execute(entrypoint)
  File "/home/vzilinas/.cache/pants/setup/bootstrap-Linux-x86_64/1.6.0/lib/python2.7/site-packages/pants/bin/pants_loader.py", line 58, in load_and_execute
    entrypoint_main()
  File "/home/vzilinas/.cache/pants/setup/bootstrap-Linux-x86_64/1.6.0/lib/python2.7/site-packages/pants/bin/pants_exe.py", line 39, in main
    PantsRunner(exiter, start_time=start_time).run()
  File "/home/vzilinas/.cache/pants/setup/bootstrap-Linux-x86_64/1.6.0/lib/python2.7/site-packages/pants/bin/pants_runner.py", line 53, in run
    return runner.run()
  File "/home/vzilinas/.cache/pants/setup/bootstrap-Linux-x86_64/1.6.0/lib/python2.7/site-packages/pants/bin/local_pants_runner.py", line 49, in run
    self._run()
  File "/home/vzilinas/.cache/pants/setup/bootstrap-Linux-x86_64/1.6.0/lib/python2.7/site-packages/pants/bin/local_pants_runner.py", line 95, in _run
    self._exiter).setup()
  File "/home/vzilinas/.cache/pants/setup/bootstrap-Linux-x86_64/1.6.0/lib/python2.7/site-packages/pants/bin/goal_runner.py", line 200, in setup
    goals, context = self._setup_context()
  File "/home/vzilinas/.cache/pants/setup/bootstrap-Linux-x86_64/1.6.0/lib/python2.7/site-packages/pants/bin/goal_runner.py", line 171, in _setup_context
    self._global_options.subproject_roots
  File "/home/vzilinas/.cache/pants/setup/bootstrap-Linux-x86_64/1.6.0/lib/python2.7/site-packages/pants/bin/goal_runner.py", line 121, in _init_graph
    graph, address_mapper = graph_helper.create_build_graph(target_roots, self._root_dir)
  File "/home/vzilinas/.cache/pants/setup/bootstrap-Linux-x86_64/1.6.0/lib/python2.7/site-packages/pants/bin/engine_initializer.py", line 101, in create_build_graph
    for _ in graph.inject_roots_closure(target_roots):
  File "/home/vzilinas/.cache/pants/setup/bootstrap-Linux-x86_64/1.6.0/lib/python2.7/site-packages/pants/engine/legacy/graph.py", line 209, in inject_roots_closure
    for address in self._inject_specs(target_roots.specs):
  File "/home/vzilinas/.cache/pants/setup/bootstrap-Linux-x86_64/1.6.0/lib/python2.7/site-packages/pants/engine/legacy/graph.py", line 259, in _inject_specs
    [Specs(specs)])
  File "/usr/local/lib/python2.7/contextlib.py", line 35, in __exit__
    self.gen.throw(type, value, traceback)
  File "/home/vzilinas/.cache/pants/setup/bootstrap-Linux-x86_64/1.6.0/lib/python2.7/site-packages/pants/engine/legacy/graph.py", line 228, in _resolve_context
    'Build graph construction failed: {} {}'.format(type(e).__name__, str(e))

Exception message: Build graph construction failed: ResolveError "report-generation-topology" was not found in namespace "src/python/report-generation-topology". Did you mean one of:
  :report_generation_topology
  :spouts-bolts-py

timestamp: 2018-06-03T21:15:01.595345
args: ['/home/vzilinas/.cache/pants/setup/bootstrap-Linux-x86_64/1.6.0/bin/pants', 'binary', 'src/python/report_generation_topology']
pid: 21245
Exception caught: (<class 'pants.build_graph.address_lookup_error.AddressLookupError'>)
  File "/home/vzilinas/.cache/pants/setup/bootstrap-Linux-x86_64/1.6.0/bin/pants", line 11, in <module>
    sys.exit(main())
  File "/home/vzilinas/.cache/pants/setup/bootstrap-Linux-x86_64/1.6.0/lib/python2.7/site-packages/pants/bin/pants_loader.py", line 69, in main
    PantsLoader.run()
  File "/home/vzilinas/.cache/pants/setup/bootstrap-Linux-x86_64/1.6.0/lib/python2.7/site-packages/pants/bin/pants_loader.py", line 65, in run
    cls.load_and_execute(entrypoint)
  File "/home/vzilinas/.cache/pants/setup/bootstrap-Linux-x86_64/1.6.0/lib/python2.7/site-packages/pants/bin/pants_loader.py", line 58, in load_and_execute
    entrypoint_main()
  File "/home/vzilinas/.cache/pants/setup/bootstrap-Linux-x86_64/1.6.0/lib/python2.7/site-packages/pants/bin/pants_exe.py", line 39, in main
    PantsRunner(exiter, start_time=start_time).run()
  File "/home/vzilinas/.cache/pants/setup/bootstrap-Linux-x86_64/1.6.0/lib/python2.7/site-packages/pants/bin/pants_runner.py", line 53, in run
    return runner.run()
  File "/home/vzilinas/.cache/pants/setup/bootstrap-Linux-x86_64/1.6.0/lib/python2.7/site-packages/pants/bin/local_pants_runner.py", line 49, in run
    self._run()
  File "/home/vzilinas/.cache/pants/setup/bootstrap-Linux-x86_64/1.6.0/lib/python2.7/site-packages/pants/bin/local_pants_runner.py", line 95, in _run
    self._exiter).setup()
  File "/home/vzilinas/.cache/pants/setup/bootstrap-Linux-x86_64/1.6.0/lib/python2.7/site-packages/pants/bin/goal_runner.py", line 200, in setup
    goals, context = self._setup_context()
  File "/home/vzilinas/.cache/pants/setup/bootstrap-Linux-x86_64/1.6.0/lib/python2.7/site-packages/pants/bin/goal_runner.py", line 171, in _setup_context
    self._global_options.subproject_roots
  File "/home/vzilinas/.cache/pants/setup/bootstrap-Linux-x86_64/1.6.0/lib/python2.7/site-packages/pants/bin/goal_runner.py", line 121, in _init_graph
    graph, address_mapper = graph_helper.create_build_graph(target_roots, self._root_dir)
  File "/home/vzilinas/.cache/pants/setup/bootstrap-Linux-x86_64/1.6.0/lib/python2.7/site-packages/pants/bin/engine_initializer.py", line 101, in create_build_graph
    for _ in graph.inject_roots_closure(target_roots):
  File "/home/vzilinas/.cache/pants/setup/bootstrap-Linux-x86_64/1.6.0/lib/python2.7/site-packages/pants/engine/legacy/graph.py", line 209, in inject_roots_closure
    for address in self._inject_specs(target_roots.specs):
  File "/home/vzilinas/.cache/pants/setup/bootstrap-Linux-x86_64/1.6.0/lib/python2.7/site-packages/pants/engine/legacy/graph.py", line 259, in _inject_specs
    [Specs(specs)])
  File "/usr/local/lib/python2.7/contextlib.py", line 35, in __exit__
    self.gen.throw(type, value, traceback)
  File "/home/vzilinas/.cache/pants/setup/bootstrap-Linux-x86_64/1.6.0/lib/python2.7/site-packages/pants/engine/legacy/graph.py", line 228, in _resolve_context
    'Build graph construction failed: {} {}'.format(type(e).__name__, str(e))

Exception message: Build graph construction failed: ResolveError Path "src/python/report_generation_topology" contains no BUILD files.

timestamp: 2018-06-03T21:15:29.207668
args: ['/home/vzilinas/.cache/pants/setup/bootstrap-Linux-x86_64/1.6.0/bin/pants', 'binary', 'src/python/report_generation_topology']
pid: 21295
Exception caught: (<class 'pants.build_graph.address_lookup_error.AddressLookupError'>)
  File "/home/vzilinas/.cache/pants/setup/bootstrap-Linux-x86_64/1.6.0/bin/pants", line 11, in <module>
    sys.exit(main())
  File "/home/vzilinas/.cache/pants/setup/bootstrap-Linux-x86_64/1.6.0/lib/python2.7/site-packages/pants/bin/pants_loader.py", line 69, in main
    PantsLoader.run()
  File "/home/vzilinas/.cache/pants/setup/bootstrap-Linux-x86_64/1.6.0/lib/python2.7/site-packages/pants/bin/pants_loader.py", line 65, in run
    cls.load_and_execute(entrypoint)
  File "/home/vzilinas/.cache/pants/setup/bootstrap-Linux-x86_64/1.6.0/lib/python2.7/site-packages/pants/bin/pants_loader.py", line 58, in load_and_execute
    entrypoint_main()
  File "/home/vzilinas/.cache/pants/setup/bootstrap-Linux-x86_64/1.6.0/lib/python2.7/site-packages/pants/bin/pants_exe.py", line 39, in main
    PantsRunner(exiter, start_time=start_time).run()
  File "/home/vzilinas/.cache/pants/setup/bootstrap-Linux-x86_64/1.6.0/lib/python2.7/site-packages/pants/bin/pants_runner.py", line 53, in run
    return runner.run()
  File "/home/vzilinas/.cache/pants/setup/bootstrap-Linux-x86_64/1.6.0/lib/python2.7/site-packages/pants/bin/local_pants_runner.py", line 49, in run
    self._run()
  File "/home/vzilinas/.cache/pants/setup/bootstrap-Linux-x86_64/1.6.0/lib/python2.7/site-packages/pants/bin/local_pants_runner.py", line 95, in _run
    self._exiter).setup()
  File "/home/vzilinas/.cache/pants/setup/bootstrap-Linux-x86_64/1.6.0/lib/python2.7/site-packages/pants/bin/goal_runner.py", line 200, in setup
    goals, context = self._setup_context()
  File "/home/vzilinas/.cache/pants/setup/bootstrap-Linux-x86_64/1.6.0/lib/python2.7/site-packages/pants/bin/goal_runner.py", line 171, in _setup_context
    self._global_options.subproject_roots
  File "/home/vzilinas/.cache/pants/setup/bootstrap-Linux-x86_64/1.6.0/lib/python2.7/site-packages/pants/bin/goal_runner.py", line 121, in _init_graph
    graph, address_mapper = graph_helper.create_build_graph(target_roots, self._root_dir)
  File "/home/vzilinas/.cache/pants/setup/bootstrap-Linux-x86_64/1.6.0/lib/python2.7/site-packages/pants/bin/engine_initializer.py", line 101, in create_build_graph
    for _ in graph.inject_roots_closure(target_roots):
  File "/home/vzilinas/.cache/pants/setup/bootstrap-Linux-x86_64/1.6.0/lib/python2.7/site-packages/pants/engine/legacy/graph.py", line 209, in inject_roots_closure
    for address in self._inject_specs(target_roots.specs):
  File "/home/vzilinas/.cache/pants/setup/bootstrap-Linux-x86_64/1.6.0/lib/python2.7/site-packages/pants/engine/legacy/graph.py", line 259, in _inject_specs
    [Specs(specs)])
  File "/usr/local/lib/python2.7/contextlib.py", line 35, in __exit__
    self.gen.throw(type, value, traceback)
  File "/home/vzilinas/.cache/pants/setup/bootstrap-Linux-x86_64/1.6.0/lib/python2.7/site-packages/pants/engine/legacy/graph.py", line 228, in _resolve_context
    'Build graph construction failed: {} {}'.format(type(e).__name__, str(e))

Exception message: Build graph construction failed: ResolveError Path "src/python/report_generation_topology" contains no BUILD files.

timestamp: 2018-06-03T21:16:31.876089
args: ['/home/vzilinas/.cache/pants/setup/bootstrap-Linux-x86_64/1.6.0/bin/pants', 'binary', 'src/python/report-generation-topology']
pid: 21338
Exception caught: (<class 'pants.build_graph.address_lookup_error.AddressLookupError'>)
  File "/home/vzilinas/.cache/pants/setup/bootstrap-Linux-x86_64/1.6.0/bin/pants", line 11, in <module>
    sys.exit(main())
  File "/home/vzilinas/.cache/pants/setup/bootstrap-Linux-x86_64/1.6.0/lib/python2.7/site-packages/pants/bin/pants_loader.py", line 69, in main
    PantsLoader.run()
  File "/home/vzilinas/.cache/pants/setup/bootstrap-Linux-x86_64/1.6.0/lib/python2.7/site-packages/pants/bin/pants_loader.py", line 65, in run
    cls.load_and_execute(entrypoint)
  File "/home/vzilinas/.cache/pants/setup/bootstrap-Linux-x86_64/1.6.0/lib/python2.7/site-packages/pants/bin/pants_loader.py", line 58, in load_and_execute
    entrypoint_main()
  File "/home/vzilinas/.cache/pants/setup/bootstrap-Linux-x86_64/1.6.0/lib/python2.7/site-packages/pants/bin/pants_exe.py", line 39, in main
    PantsRunner(exiter, start_time=start_time).run()
  File "/home/vzilinas/.cache/pants/setup/bootstrap-Linux-x86_64/1.6.0/lib/python2.7/site-packages/pants/bin/pants_runner.py", line 53, in run
    return runner.run()
  File "/home/vzilinas/.cache/pants/setup/bootstrap-Linux-x86_64/1.6.0/lib/python2.7/site-packages/pants/bin/local_pants_runner.py", line 49, in run
    self._run()
  File "/home/vzilinas/.cache/pants/setup/bootstrap-Linux-x86_64/1.6.0/lib/python2.7/site-packages/pants/bin/local_pants_runner.py", line 95, in _run
    self._exiter).setup()
  File "/home/vzilinas/.cache/pants/setup/bootstrap-Linux-x86_64/1.6.0/lib/python2.7/site-packages/pants/bin/goal_runner.py", line 200, in setup
    goals, context = self._setup_context()
  File "/home/vzilinas/.cache/pants/setup/bootstrap-Linux-x86_64/1.6.0/lib/python2.7/site-packages/pants/bin/goal_runner.py", line 171, in _setup_context
    self._global_options.subproject_roots
  File "/home/vzilinas/.cache/pants/setup/bootstrap-Linux-x86_64/1.6.0/lib/python2.7/site-packages/pants/bin/goal_runner.py", line 121, in _init_graph
    graph, address_mapper = graph_helper.create_build_graph(target_roots, self._root_dir)
  File "/home/vzilinas/.cache/pants/setup/bootstrap-Linux-x86_64/1.6.0/lib/python2.7/site-packages/pants/bin/engine_initializer.py", line 101, in create_build_graph
    for _ in graph.inject_roots_closure(target_roots):
  File "/home/vzilinas/.cache/pants/setup/bootstrap-Linux-x86_64/1.6.0/lib/python2.7/site-packages/pants/engine/legacy/graph.py", line 209, in inject_roots_closure
    for address in self._inject_specs(target_roots.specs):
  File "/home/vzilinas/.cache/pants/setup/bootstrap-Linux-x86_64/1.6.0/lib/python2.7/site-packages/pants/engine/legacy/graph.py", line 259, in _inject_specs
    [Specs(specs)])
  File "/usr/local/lib/python2.7/contextlib.py", line 35, in __exit__
    self.gen.throw(type, value, traceback)
  File "/home/vzilinas/.cache/pants/setup/bootstrap-Linux-x86_64/1.6.0/lib/python2.7/site-packages/pants/engine/legacy/graph.py", line 228, in _resolve_context
    'Build graph construction failed: {} {}'.format(type(e).__name__, str(e))

Exception message: Build graph construction failed: ResolveError "report-generation-topology" was not found in namespace "src/python/report-generation-topology". Did you mean one of:
  :report_generation_topology
  :spouts-bolts-py

timestamp: 2018-06-04T18:32:55.104085
args: ['/home/vzilinas/.cache/pants/setup/bootstrap-Linux-x86_64/1.6.0/bin/pants', 'binary', 'src/python/report-generation-topology']
pid: 3021
Exception caught: (<class 'pants.engine.round_engine.MissingProductError'>)
  File "/home/vzilinas/.cache/pants/setup/bootstrap-Linux-x86_64/1.6.0/bin/pants", line 11, in <module>
    sys.exit(main())
  File "/home/vzilinas/.cache/pants/setup/bootstrap-Linux-x86_64/1.6.0/lib/python2.7/site-packages/pants/bin/pants_loader.py", line 69, in main
    PantsLoader.run()
  File "/home/vzilinas/.cache/pants/setup/bootstrap-Linux-x86_64/1.6.0/lib/python2.7/site-packages/pants/bin/pants_loader.py", line 65, in run
    cls.load_and_execute(entrypoint)
  File "/home/vzilinas/.cache/pants/setup/bootstrap-Linux-x86_64/1.6.0/lib/python2.7/site-packages/pants/bin/pants_loader.py", line 58, in load_and_execute
    entrypoint_main()
  File "/home/vzilinas/.cache/pants/setup/bootstrap-Linux-x86_64/1.6.0/lib/python2.7/site-packages/pants/bin/pants_exe.py", line 39, in main
    PantsRunner(exiter, start_time=start_time).run()
  File "/home/vzilinas/.cache/pants/setup/bootstrap-Linux-x86_64/1.6.0/lib/python2.7/site-packages/pants/bin/pants_runner.py", line 53, in run
    return runner.run()
  File "/home/vzilinas/.cache/pants/setup/bootstrap-Linux-x86_64/1.6.0/lib/python2.7/site-packages/pants/bin/local_pants_runner.py", line 49, in run
    self._run()
  File "/home/vzilinas/.cache/pants/setup/bootstrap-Linux-x86_64/1.6.0/lib/python2.7/site-packages/pants/bin/local_pants_runner.py", line 97, in _run
    goal_runner_result = goal_runner.run()
  File "/home/vzilinas/.cache/pants/setup/bootstrap-Linux-x86_64/1.6.0/lib/python2.7/site-packages/pants/bin/goal_runner.py", line 269, in run
    result = self._execute_engine()
  File "/home/vzilinas/.cache/pants/setup/bootstrap-Linux-x86_64/1.6.0/lib/python2.7/site-packages/pants/bin/goal_runner.py", line 254, in _execute_engine
    sorted_goal_infos = engine.sort_goals(self._context, self._goals)
  File "/home/vzilinas/.cache/pants/setup/bootstrap-Linux-x86_64/1.6.0/lib/python2.7/site-packages/pants/engine/round_engine.py", line 201, in sort_goals
    self._visit_goal(goal, context, goal_info_by_goal)
  File "/home/vzilinas/.cache/pants/setup/bootstrap-Linux-x86_64/1.6.0/lib/python2.7/site-packages/pants/engine/round_engine.py", line 186, in _visit_goal
    self._visit_goal(goal_dependency, context, goal_info_by_goal)
  File "/home/vzilinas/.cache/pants/setup/bootstrap-Linux-x86_64/1.6.0/lib/python2.7/site-packages/pants/engine/round_engine.py", line 186, in _visit_goal
    self._visit_goal(goal_dependency, context, goal_info_by_goal)
  File "/home/vzilinas/.cache/pants/setup/bootstrap-Linux-x86_64/1.6.0/lib/python2.7/site-packages/pants/engine/round_engine.py", line 180, in _visit_goal
    .format(name=task_name, action=task_type.__name__, error=e))

Exception message: Could not satisfy data dependencies for goal 'wire' with action WireGen_gen_wire: u"No producers registered for 'jvm_build_tools_classpath_callbacks'"

timestamp: 2018-06-04T18:33:19.441101
args: ['/home/vzilinas/.cache/pants/setup/bootstrap-Linux-x86_64/1.6.0/bin/pants', 'binary', 'src/python/report-generation-topology']
pid: 3073
Exception caught: (<class 'pants.option.config.ConfigValidationError'>)
  File "/home/vzilinas/.cache/pants/setup/bootstrap-Linux-x86_64/1.6.0/bin/pants", line 11, in <module>
    sys.exit(main())
  File "/home/vzilinas/.cache/pants/setup/bootstrap-Linux-x86_64/1.6.0/lib/python2.7/site-packages/pants/bin/pants_loader.py", line 69, in main
    PantsLoader.run()
  File "/home/vzilinas/.cache/pants/setup/bootstrap-Linux-x86_64/1.6.0/lib/python2.7/site-packages/pants/bin/pants_loader.py", line 65, in run
    cls.load_and_execute(entrypoint)
  File "/home/vzilinas/.cache/pants/setup/bootstrap-Linux-x86_64/1.6.0/lib/python2.7/site-packages/pants/bin/pants_loader.py", line 58, in load_and_execute
    entrypoint_main()
  File "/home/vzilinas/.cache/pants/setup/bootstrap-Linux-x86_64/1.6.0/lib/python2.7/site-packages/pants/bin/pants_exe.py", line 39, in main
    PantsRunner(exiter, start_time=start_time).run()
  File "/home/vzilinas/.cache/pants/setup/bootstrap-Linux-x86_64/1.6.0/lib/python2.7/site-packages/pants/bin/pants_runner.py", line 53, in run
    return runner.run()
  File "/home/vzilinas/.cache/pants/setup/bootstrap-Linux-x86_64/1.6.0/lib/python2.7/site-packages/pants/bin/local_pants_runner.py", line 49, in run
    self._run()
  File "/home/vzilinas/.cache/pants/setup/bootstrap-Linux-x86_64/1.6.0/lib/python2.7/site-packages/pants/bin/local_pants_runner.py", line 68, in _run
    options_bootstrapper.verify_configs_against_options(options)
  File "/home/vzilinas/.cache/pants/setup/bootstrap-Linux-x86_64/1.6.0/lib/python2.7/site-packages/pants/option/options_bootstrapper.py", line 183, in verify_configs_against_options
    raise Config.ConfigValidationError("Invalid config entries detected. "

Exception message: Invalid config entries detected. See log for details on which entries to update or remove.
(Specify --no-verify-config to disable this check.)

timestamp: 2018-06-04T18:33:31.257698
args: ['/home/vzilinas/.cache/pants/setup/bootstrap-Linux-x86_64/1.6.0/bin/pants', 'binary', 'src/python/report-generation-topology']
pid: 3092
Exception caught: (<class 'pants.engine.round_engine.MissingProductError'>)
  File "/home/vzilinas/.cache/pants/setup/bootstrap-Linux-x86_64/1.6.0/bin/pants", line 11, in <module>
    sys.exit(main())
  File "/home/vzilinas/.cache/pants/setup/bootstrap-Linux-x86_64/1.6.0/lib/python2.7/site-packages/pants/bin/pants_loader.py", line 69, in main
    PantsLoader.run()
  File "/home/vzilinas/.cache/pants/setup/bootstrap-Linux-x86_64/1.6.0/lib/python2.7/site-packages/pants/bin/pants_loader.py", line 65, in run
    cls.load_and_execute(entrypoint)
  File "/home/vzilinas/.cache/pants/setup/bootstrap-Linux-x86_64/1.6.0/lib/python2.7/site-packages/pants/bin/pants_loader.py", line 58, in load_and_execute
    entrypoint_main()
  File "/home/vzilinas/.cache/pants/setup/bootstrap-Linux-x86_64/1.6.0/lib/python2.7/site-packages/pants/bin/pants_exe.py", line 39, in main
    PantsRunner(exiter, start_time=start_time).run()
  File "/home/vzilinas/.cache/pants/setup/bootstrap-Linux-x86_64/1.6.0/lib/python2.7/site-packages/pants/bin/pants_runner.py", line 53, in run
    return runner.run()
  File "/home/vzilinas/.cache/pants/setup/bootstrap-Linux-x86_64/1.6.0/lib/python2.7/site-packages/pants/bin/local_pants_runner.py", line 49, in run
    self._run()
  File "/home/vzilinas/.cache/pants/setup/bootstrap-Linux-x86_64/1.6.0/lib/python2.7/site-packages/pants/bin/local_pants_runner.py", line 97, in _run
    goal_runner_result = goal_runner.run()
  File "/home/vzilinas/.cache/pants/setup/bootstrap-Linux-x86_64/1.6.0/lib/python2.7/site-packages/pants/bin/goal_runner.py", line 269, in run
    result = self._execute_engine()
  File "/home/vzilinas/.cache/pants/setup/bootstrap-Linux-x86_64/1.6.0/lib/python2.7/site-packages/pants/bin/goal_runner.py", line 254, in _execute_engine
    sorted_goal_infos = engine.sort_goals(self._context, self._goals)
  File "/home/vzilinas/.cache/pants/setup/bootstrap-Linux-x86_64/1.6.0/lib/python2.7/site-packages/pants/engine/round_engine.py", line 201, in sort_goals
    self._visit_goal(goal, context, goal_info_by_goal)
  File "/home/vzilinas/.cache/pants/setup/bootstrap-Linux-x86_64/1.6.0/lib/python2.7/site-packages/pants/engine/round_engine.py", line 186, in _visit_goal
    self._visit_goal(goal_dependency, context, goal_info_by_goal)
  File "/home/vzilinas/.cache/pants/setup/bootstrap-Linux-x86_64/1.6.0/lib/python2.7/site-packages/pants/engine/round_engine.py", line 186, in _visit_goal
    self._visit_goal(goal_dependency, context, goal_info_by_goal)
  File "/home/vzilinas/.cache/pants/setup/bootstrap-Linux-x86_64/1.6.0/lib/python2.7/site-packages/pants/engine/round_engine.py", line 180, in _visit_goal
    .format(name=task_name, action=task_type.__name__, error=e))

Exception message: Could not satisfy data dependencies for goal 'wire' with action WireGen_gen_wire: u"No producers registered for 'jvm_build_tools_classpath_callbacks'"

timestamp: 2018-06-04T18:33:48.133305
args: ['/home/vzilinas/.cache/pants/setup/bootstrap-Linux-x86_64/1.6.0/bin/pants', '--explain', 'binary', 'src/python/report-generation-topology']
pid: 3132
Exception caught: (<class 'pants.engine.round_engine.MissingProductError'>)
  File "/home/vzilinas/.cache/pants/setup/bootstrap-Linux-x86_64/1.6.0/bin/pants", line 11, in <module>
    sys.exit(main())
  File "/home/vzilinas/.cache/pants/setup/bootstrap-Linux-x86_64/1.6.0/lib/python2.7/site-packages/pants/bin/pants_loader.py", line 69, in main
    PantsLoader.run()
  File "/home/vzilinas/.cache/pants/setup/bootstrap-Linux-x86_64/1.6.0/lib/python2.7/site-packages/pants/bin/pants_loader.py", line 65, in run
    cls.load_and_execute(entrypoint)
  File "/home/vzilinas/.cache/pants/setup/bootstrap-Linux-x86_64/1.6.0/lib/python2.7/site-packages/pants/bin/pants_loader.py", line 58, in load_and_execute
    entrypoint_main()
  File "/home/vzilinas/.cache/pants/setup/bootstrap-Linux-x86_64/1.6.0/lib/python2.7/site-packages/pants/bin/pants_exe.py", line 39, in main
    PantsRunner(exiter, start_time=start_time).run()
  File "/home/vzilinas/.cache/pants/setup/bootstrap-Linux-x86_64/1.6.0/lib/python2.7/site-packages/pants/bin/pants_runner.py", line 53, in run
    return runner.run()
  File "/home/vzilinas/.cache/pants/setup/bootstrap-Linux-x86_64/1.6.0/lib/python2.7/site-packages/pants/bin/local_pants_runner.py", line 49, in run
    self._run()
  File "/home/vzilinas/.cache/pants/setup/bootstrap-Linux-x86_64/1.6.0/lib/python2.7/site-packages/pants/bin/local_pants_runner.py", line 97, in _run
    goal_runner_result = goal_runner.run()
  File "/home/vzilinas/.cache/pants/setup/bootstrap-Linux-x86_64/1.6.0/lib/python2.7/site-packages/pants/bin/goal_runner.py", line 269, in run
    result = self._execute_engine()
  File "/home/vzilinas/.cache/pants/setup/bootstrap-Linux-x86_64/1.6.0/lib/python2.7/site-packages/pants/bin/goal_runner.py", line 254, in _execute_engine
    sorted_goal_infos = engine.sort_goals(self._context, self._goals)
  File "/home/vzilinas/.cache/pants/setup/bootstrap-Linux-x86_64/1.6.0/lib/python2.7/site-packages/pants/engine/round_engine.py", line 201, in sort_goals
    self._visit_goal(goal, context, goal_info_by_goal)
  File "/home/vzilinas/.cache/pants/setup/bootstrap-Linux-x86_64/1.6.0/lib/python2.7/site-packages/pants/engine/round_engine.py", line 186, in _visit_goal
    self._visit_goal(goal_dependency, context, goal_info_by_goal)
  File "/home/vzilinas/.cache/pants/setup/bootstrap-Linux-x86_64/1.6.0/lib/python2.7/site-packages/pants/engine/round_engine.py", line 186, in _visit_goal
    self._visit_goal(goal_dependency, context, goal_info_by_goal)
  File "/home/vzilinas/.cache/pants/setup/bootstrap-Linux-x86_64/1.6.0/lib/python2.7/site-packages/pants/engine/round_engine.py", line 180, in _visit_goal
    .format(name=task_name, action=task_type.__name__, error=e))

Exception message: Could not satisfy data dependencies for goal 'wire' with action WireGen_gen_wire: u"No producers registered for 'jvm_build_tools_classpath_callbacks'"

timestamp: 2018-06-04T18:39:31.485165
args: ['/home/vzilinas/.cache/pants/setup/bootstrap-Linux-x86_64/1.6.0/bin/pants', 'binary', 'src/python/report-generation-topology']
pid: 3318
Exception caught: (<class 'pants.engine.round_engine.MissingProductError'>)
  File "/home/vzilinas/.cache/pants/setup/bootstrap-Linux-x86_64/1.6.0/bin/pants", line 11, in <module>
    sys.exit(main())
  File "/home/vzilinas/.cache/pants/setup/bootstrap-Linux-x86_64/1.6.0/lib/python2.7/site-packages/pants/bin/pants_loader.py", line 69, in main
    PantsLoader.run()
  File "/home/vzilinas/.cache/pants/setup/bootstrap-Linux-x86_64/1.6.0/lib/python2.7/site-packages/pants/bin/pants_loader.py", line 65, in run
    cls.load_and_execute(entrypoint)
  File "/home/vzilinas/.cache/pants/setup/bootstrap-Linux-x86_64/1.6.0/lib/python2.7/site-packages/pants/bin/pants_loader.py", line 58, in load_and_execute
    entrypoint_main()
  File "/home/vzilinas/.cache/pants/setup/bootstrap-Linux-x86_64/1.6.0/lib/python2.7/site-packages/pants/bin/pants_exe.py", line 39, in main
    PantsRunner(exiter, start_time=start_time).run()
  File "/home/vzilinas/.cache/pants/setup/bootstrap-Linux-x86_64/1.6.0/lib/python2.7/site-packages/pants/bin/pants_runner.py", line 53, in run
    return runner.run()
  File "/home/vzilinas/.cache/pants/setup/bootstrap-Linux-x86_64/1.6.0/lib/python2.7/site-packages/pants/bin/local_pants_runner.py", line 49, in run
    self._run()
  File "/home/vzilinas/.cache/pants/setup/bootstrap-Linux-x86_64/1.6.0/lib/python2.7/site-packages/pants/bin/local_pants_runner.py", line 97, in _run
    goal_runner_result = goal_runner.run()
  File "/home/vzilinas/.cache/pants/setup/bootstrap-Linux-x86_64/1.6.0/lib/python2.7/site-packages/pants/bin/goal_runner.py", line 269, in run
    result = self._execute_engine()
  File "/home/vzilinas/.cache/pants/setup/bootstrap-Linux-x86_64/1.6.0/lib/python2.7/site-packages/pants/bin/goal_runner.py", line 254, in _execute_engine
    sorted_goal_infos = engine.sort_goals(self._context, self._goals)
  File "/home/vzilinas/.cache/pants/setup/bootstrap-Linux-x86_64/1.6.0/lib/python2.7/site-packages/pants/engine/round_engine.py", line 201, in sort_goals
    self._visit_goal(goal, context, goal_info_by_goal)
  File "/home/vzilinas/.cache/pants/setup/bootstrap-Linux-x86_64/1.6.0/lib/python2.7/site-packages/pants/engine/round_engine.py", line 186, in _visit_goal
    self._visit_goal(goal_dependency, context, goal_info_by_goal)
  File "/home/vzilinas/.cache/pants/setup/bootstrap-Linux-x86_64/1.6.0/lib/python2.7/site-packages/pants/engine/round_engine.py", line 186, in _visit_goal
    self._visit_goal(goal_dependency, context, goal_info_by_goal)
  File "/home/vzilinas/.cache/pants/setup/bootstrap-Linux-x86_64/1.6.0/lib/python2.7/site-packages/pants/engine/round_engine.py", line 180, in _visit_goal
    .format(name=task_name, action=task_type.__name__, error=e))

Exception message: Could not satisfy data dependencies for goal 'wire' with action WireGen_gen_wire: u"No producers registered for 'jvm_build_tools_classpath_callbacks'"

timestamp: 2018-06-04T18:39:45.351981
args: ['/home/vzilinas/.cache/pants/setup/bootstrap-Linux-x86_64/1.6.0/bin/pants', 'binary', 'src/python/report-generation-topology']
pid: 3357
Exception caught: (<class 'pex.compiler.CompilationFailure'>)
  File "/home/vzilinas/.cache/pants/setup/bootstrap-Linux-x86_64/1.6.0/bin/pants", line 11, in <module>
    sys.exit(main())
  File "/home/vzilinas/.cache/pants/setup/bootstrap-Linux-x86_64/1.6.0/lib/python2.7/site-packages/pants/bin/pants_loader.py", line 69, in main
    PantsLoader.run()
  File "/home/vzilinas/.cache/pants/setup/bootstrap-Linux-x86_64/1.6.0/lib/python2.7/site-packages/pants/bin/pants_loader.py", line 65, in run
    cls.load_and_execute(entrypoint)
  File "/home/vzilinas/.cache/pants/setup/bootstrap-Linux-x86_64/1.6.0/lib/python2.7/site-packages/pants/bin/pants_loader.py", line 58, in load_and_execute
    entrypoint_main()
  File "/home/vzilinas/.cache/pants/setup/bootstrap-Linux-x86_64/1.6.0/lib/python2.7/site-packages/pants/bin/pants_exe.py", line 39, in main
    PantsRunner(exiter, start_time=start_time).run()
  File "/home/vzilinas/.cache/pants/setup/bootstrap-Linux-x86_64/1.6.0/lib/python2.7/site-packages/pants/bin/pants_runner.py", line 53, in run
    return runner.run()
  File "/home/vzilinas/.cache/pants/setup/bootstrap-Linux-x86_64/1.6.0/lib/python2.7/site-packages/pants/bin/local_pants_runner.py", line 49, in run
    self._run()
  File "/home/vzilinas/.cache/pants/setup/bootstrap-Linux-x86_64/1.6.0/lib/python2.7/site-packages/pants/bin/local_pants_runner.py", line 97, in _run
    goal_runner_result = goal_runner.run()
  File "/home/vzilinas/.cache/pants/setup/bootstrap-Linux-x86_64/1.6.0/lib/python2.7/site-packages/pants/bin/goal_runner.py", line 269, in run
    result = self._execute_engine()
  File "/home/vzilinas/.cache/pants/setup/bootstrap-Linux-x86_64/1.6.0/lib/python2.7/site-packages/pants/bin/goal_runner.py", line 257, in _execute_engine
    result = engine.execute(self._context, self._goals)
  File "/home/vzilinas/.cache/pants/setup/bootstrap-Linux-x86_64/1.6.0/lib/python2.7/site-packages/pants/engine/legacy_engine.py", line 26, in execute
    self.attempt(context, goals)
  File "/home/vzilinas/.cache/pants/setup/bootstrap-Linux-x86_64/1.6.0/lib/python2.7/site-packages/pants/engine/round_engine.py", line 233, in attempt
    goal_executor.attempt(explain)
  File "/home/vzilinas/.cache/pants/setup/bootstrap-Linux-x86_64/1.6.0/lib/python2.7/site-packages/pants/engine/round_engine.py", line 49, in attempt
    task.execute()
  File "/home/vzilinas/.cache/pants/setup/bootstrap-Linux-x86_64/1.6.0/lib/python2.7/site-packages/pants/backend/python/tasks/gather_sources.py", line 50, in execute
    pex = self._get_pex_for_versioned_targets(interpreter, invalidation_check.all_vts)
  File "/home/vzilinas/.cache/pants/setup/bootstrap-Linux-x86_64/1.6.0/lib/python2.7/site-packages/pants/backend/python/tasks/gather_sources.py", line 82, in _get_pex_for_versioned_targets
    self._build_pex(interpreter, safe_path, [vt.target for vt in versioned_targets])
  File "/home/vzilinas/.cache/pants/setup/bootstrap-Linux-x86_64/1.6.0/lib/python2.7/site-packages/pants/backend/python/tasks/gather_sources.py", line 89, in _build_pex
    builder.freeze()
  File "/home/vzilinas/.cache/pants/setup/bootstrap-Linux-x86_64/1.6.0/lib/python2.7/site-packages/pex/pex_builder.py", line 455, in freeze
    self._precompile_source()
  File "/home/vzilinas/.cache/pants/setup/bootstrap-Linux-x86_64/1.6.0/lib/python2.7/site-packages/pex/pex_builder.py", line 378, in _precompile_source
    compiled_relpaths = compiler.compile(self._chroot.path(), source_relpaths)
  File "/home/vzilinas/.cache/pants/setup/bootstrap-Linux-x86_64/1.6.0/lib/python2.7/site-packages/pex/compiler.py", line 89, in compile
    'encountered %r during bytecode compilation.\nstderr was:\n%s\n' % (e, e.stderr)

Exception message: encountered NonZeroExit("received exit code 1 during execution of `[u'/usr/local/bin/python2.7', '/tmp/tmpaiGuzl']` while trying to execute `[u'/usr/local/bin/python2.7', '/tmp/tmpaiGuzl']`",) during bytecode compilation.
stderr was:
Encountered 1 errors compiling 56 files:
  report-generation-topology/kafka_input_spout.py:   File "report-generation-topology/kafka_input_spout.py", line 25
    message = message.value.decode('utf-8'))
                                           ^
SyntaxError: invalid syntax




timestamp: 2018-06-04T22:08:57.338001
args: ['/home/vzilinas/.cache/pants/setup/bootstrap-Linux-x86_64/1.6.0/bin/pants', 'binary', 'src/python/report-generation-topology']
pid: 9094
Exception caught: (<class 'pants.build_graph.address_lookup_error.AddressLookupError'>)
  File "/home/vzilinas/.cache/pants/setup/bootstrap-Linux-x86_64/1.6.0/bin/pants", line 11, in <module>
    sys.exit(main())
  File "/home/vzilinas/.cache/pants/setup/bootstrap-Linux-x86_64/1.6.0/lib/python2.7/site-packages/pants/bin/pants_loader.py", line 69, in main
    PantsLoader.run()
  File "/home/vzilinas/.cache/pants/setup/bootstrap-Linux-x86_64/1.6.0/lib/python2.7/site-packages/pants/bin/pants_loader.py", line 65, in run
    cls.load_and_execute(entrypoint)
  File "/home/vzilinas/.cache/pants/setup/bootstrap-Linux-x86_64/1.6.0/lib/python2.7/site-packages/pants/bin/pants_loader.py", line 58, in load_and_execute
    entrypoint_main()
  File "/home/vzilinas/.cache/pants/setup/bootstrap-Linux-x86_64/1.6.0/lib/python2.7/site-packages/pants/bin/pants_exe.py", line 39, in main
    PantsRunner(exiter, start_time=start_time).run()
  File "/home/vzilinas/.cache/pants/setup/bootstrap-Linux-x86_64/1.6.0/lib/python2.7/site-packages/pants/bin/pants_runner.py", line 53, in run
    return runner.run()
  File "/home/vzilinas/.cache/pants/setup/bootstrap-Linux-x86_64/1.6.0/lib/python2.7/site-packages/pants/bin/local_pants_runner.py", line 49, in run
    self._run()
  File "/home/vzilinas/.cache/pants/setup/bootstrap-Linux-x86_64/1.6.0/lib/python2.7/site-packages/pants/bin/local_pants_runner.py", line 95, in _run
    self._exiter).setup()
  File "/home/vzilinas/.cache/pants/setup/bootstrap-Linux-x86_64/1.6.0/lib/python2.7/site-packages/pants/bin/goal_runner.py", line 200, in setup
    goals, context = self._setup_context()
  File "/home/vzilinas/.cache/pants/setup/bootstrap-Linux-x86_64/1.6.0/lib/python2.7/site-packages/pants/bin/goal_runner.py", line 171, in _setup_context
    self._global_options.subproject_roots
  File "/home/vzilinas/.cache/pants/setup/bootstrap-Linux-x86_64/1.6.0/lib/python2.7/site-packages/pants/bin/goal_runner.py", line 121, in _init_graph
    graph, address_mapper = graph_helper.create_build_graph(target_roots, self._root_dir)
  File "/home/vzilinas/.cache/pants/setup/bootstrap-Linux-x86_64/1.6.0/lib/python2.7/site-packages/pants/bin/engine_initializer.py", line 101, in create_build_graph
    for _ in graph.inject_roots_closure(target_roots):
  File "/home/vzilinas/.cache/pants/setup/bootstrap-Linux-x86_64/1.6.0/lib/python2.7/site-packages/pants/engine/legacy/graph.py", line 209, in inject_roots_closure
    for address in self._inject_specs(target_roots.specs):
  File "/home/vzilinas/.cache/pants/setup/bootstrap-Linux-x86_64/1.6.0/lib/python2.7/site-packages/pants/engine/legacy/graph.py", line 259, in _inject_specs
    [Specs(specs)])
  File "/usr/local/lib/python2.7/contextlib.py", line 35, in __exit__
    self.gen.throw(type, value, traceback)
  File "/home/vzilinas/.cache/pants/setup/bootstrap-Linux-x86_64/1.6.0/lib/python2.7/site-packages/pants/engine/legacy/graph.py", line 228, in _resolve_context
    'Build graph construction failed: {} {}'.format(type(e).__name__, str(e))

Exception message: Build graph construction failed: DuplicateNameError An object already exists at 'src/python/report-generation-topology/BUILD' with name 'report-generation-topology': PythonLibraryAdaptor(name='report-generation-topology', sources=<pants.engine.legacy.structs.Globs object at 0x7f019a226150>, type_alias=u'python_library').  Cannot map PythonTargetAdaptor(dependencies=[':report-generation-topology', '3rdparty/python:heronpy', '3rdparty/python:six', '3rdparty/python:kafka-python'], name='report-generation-topology', source='report_generation_topology.py', type_alias=u'python_binary')

